[2024-06-16T16:36:57.305+0530] {logging_mixin.py:188} INFO - Changing /mnt/d/Programs/weather etl/logs/dag_id=weather_dag_etl/run_id=manual__2024-06-16T11:04:54.555972+00:00/task_id=check_whether_api_ready permission to 509
[2024-06-16T16:36:58.096+0530] {logging_mixin.py:188} INFO - Changing /mnt/d/Programs/weather etl/logs/dag_id=weather_dag_etl/run_id=manual__2024-06-16T11:04:54.555972+00:00/task_id=check_whether_api_ready permission to 509
[2024-06-16T16:36:58.133+0530] {taskinstance.py:1946} INFO - Dependencies not met for <TaskInstance: weather_dag_etl.check_whether_api_ready manual__2024-06-16T11:04:54.555972+00:00 [up_for_retry]>, dependency 'Not In Retry Period' FAILED: Task is not ready for retry yet but will be retried automatically. Current date is 2024-06-16T11:06:58.133003+00:00 and task will be retried at 2024-06-16T11:07:59.516888+00:00.
[2024-06-16T16:36:58.146+0530] {local_task_job_runner.py:160} INFO - Task is not able to be run
[2024-06-16T16:57:45.889+0530] {logging_mixin.py:188} INFO - Changing /mnt/d/Programs/weather etl/logs/dag_id=weather_dag_etl/run_id=manual__2024-06-16T11:04:54.555972+00:00/task_id=check_whether_api_ready permission to 509
[2024-06-16T16:57:46.232+0530] {logging_mixin.py:188} INFO - Changing /mnt/d/Programs/weather etl/logs/dag_id=weather_dag_etl/run_id=manual__2024-06-16T11:04:54.555972+00:00/task_id=check_whether_api_ready permission to 509
[2024-06-16T16:57:46.270+0530] {taskinstance.py:1956} INFO - Dependencies all met for dep_context=non-requeueable deps ti=<TaskInstance: weather_dag_etl.check_whether_api_ready manual__2024-06-16T11:04:54.555972+00:00 [queued]>
[2024-06-16T16:57:46.322+0530] {taskinstance.py:1956} INFO - Dependencies all met for dep_context=requeueable deps ti=<TaskInstance: weather_dag_etl.check_whether_api_ready manual__2024-06-16T11:04:54.555972+00:00 [queued]>
[2024-06-16T16:57:46.325+0530] {taskinstance.py:2170} INFO - Starting attempt 2 of 3
[2024-06-16T16:57:46.465+0530] {taskinstance.py:2191} INFO - Executing <Task(HttpSensor): check_whether_api_ready> on 2024-06-16 11:04:54.555972+00:00
[2024-06-16T16:57:46.473+0530] {standard_task_runner.py:60} INFO - Started process 561 to run task
[2024-06-16T16:57:46.485+0530] {standard_task_runner.py:87} INFO - Running: ['airflow', 'tasks', 'run', 'weather_dag_etl', 'check_whether_api_ready', 'manual__2024-06-16T11:04:54.555972+00:00', '--job-id', '10', '--raw', '--subdir', 'DAGS_FOLDER/weather_dag_etl.py', '--cfg-path', '/tmp/tmplhvs74fp']
[2024-06-16T16:57:46.491+0530] {standard_task_runner.py:88} INFO - Job 10: Subtask check_whether_api_ready
[2024-06-16T16:57:46.713+0530] {logging_mixin.py:188} INFO - Changing /mnt/d/Programs/weather etl/logs/dag_id=weather_dag_etl/run_id=manual__2024-06-16T11:04:54.555972+00:00/task_id=check_whether_api_ready permission to 509
[2024-06-16T16:57:46.718+0530] {task_command.py:423} INFO - Running <TaskInstance: weather_dag_etl.check_whether_api_ready manual__2024-06-16T11:04:54.555972+00:00 [running]> on host DESKTOP-ATOQU9B.localdomain
[2024-06-16T16:57:47.409+0530] {taskinstance.py:2480} INFO - Exporting env vars: AIRFLOW_CTX_DAG_EMAIL='email@udit.com' AIRFLOW_CTX_DAG_OWNER='udit' AIRFLOW_CTX_DAG_ID='weather_dag_etl' AIRFLOW_CTX_TASK_ID='check_whether_api_ready' AIRFLOW_CTX_EXECUTION_DATE='2024-06-16T11:04:54.555972+00:00' AIRFLOW_CTX_TRY_NUMBER='2' AIRFLOW_CTX_DAG_RUN_ID='manual__2024-06-16T11:04:54.555972+00:00'
[2024-06-16T16:57:47.411+0530] {http.py:130} INFO - Poking: https://api.openweathermap.org/data/2.5/weather?q=Portland&APPID=***
[2024-06-16T16:57:47.430+0530] {base.py:83} INFO - Using connection ID 'weathermap_api' for task execution.
[2024-06-16T16:57:47.677+0530] {http.py:178} ERROR - HTTP error: Not Found
[2024-06-16T16:57:47.679+0530] {http.py:179} ERROR - <html>
<head><title>404 Not Found</title></head>
<body>
<center><h1>404 Not Found</h1></center>
<hr><center>openresty</center>
</body>
</html>

[2024-06-16T16:58:07.157+0530] {process_utils.py:131} INFO - Sending 15 to group 561. PIDs of all processes in the group: [561]
[2024-06-16T16:58:07.161+0530] {process_utils.py:86} INFO - Sending the signal 15 to group 561
[2024-06-16T16:58:07.164+0530] {taskinstance.py:2450} ERROR - Received SIGTERM. Terminating subprocesses.
[2024-06-16T16:58:07.192+0530] {taskinstance.py:2698} ERROR - Task failed with exception
Traceback (most recent call last):
  File "/mnt/d/Programs/weather etl/airflow-venv/lib/python3.8/site-packages/airflow/models/taskinstance.py", line 433, in _execute_task
    result = execute_callable(context=context, **execute_callable_kwargs)
  File "/mnt/d/Programs/weather etl/airflow-venv/lib/python3.8/site-packages/airflow/sensors/base.py", line 293, in execute
    time.sleep(self._get_next_poke_interval(started_at, run_duration, try_number))
  File "/mnt/d/Programs/weather etl/airflow-venv/lib/python3.8/site-packages/airflow/models/taskinstance.py", line 2452, in signal_handler
    raise AirflowException("Task received SIGTERM signal")
airflow.exceptions.AirflowException: Task received SIGTERM signal
[2024-06-16T16:58:07.216+0530] {taskinstance.py:1138} INFO - Marking task as UP_FOR_RETRY. dag_id=weather_dag_etl, task_id=check_whether_api_ready, execution_date=20240616T110454, start_date=20240616T112746, end_date=20240616T112807
[2024-06-16T16:58:08.341+0530] {standard_task_runner.py:107} ERROR - Failed to execute job 10 for task check_whether_api_ready (Task received SIGTERM signal; 561)
