[2024-06-16T16:50:19.655+0530] {logging_mixin.py:188} INFO - Changing /mnt/d/Programs/weather etl/logs/dag_id=weather_dag_etl/run_id=manual__2024-06-16T11:02:22.554439+00:00/task_id=check_whether_api_ready permission to 509
[2024-06-16T16:50:20.014+0530] {logging_mixin.py:188} INFO - Changing /mnt/d/Programs/weather etl/logs/dag_id=weather_dag_etl/run_id=manual__2024-06-16T11:02:22.554439+00:00/task_id=check_whether_api_ready permission to 509
[2024-06-16T16:50:20.062+0530] {taskinstance.py:1956} INFO - Dependencies all met for dep_context=non-requeueable deps ti=<TaskInstance: weather_dag_etl.check_whether_api_ready manual__2024-06-16T11:02:22.554439+00:00 [queued]>
[2024-06-16T16:50:20.100+0530] {taskinstance.py:1956} INFO - Dependencies all met for dep_context=requeueable deps ti=<TaskInstance: weather_dag_etl.check_whether_api_ready manual__2024-06-16T11:02:22.554439+00:00 [queued]>
[2024-06-16T16:50:20.104+0530] {taskinstance.py:2170} INFO - Starting attempt 2 of 3
[2024-06-16T16:50:20.264+0530] {taskinstance.py:2191} INFO - Executing <Task(HttpSensor): check_whether_api_ready> on 2024-06-16 11:02:22.554439+00:00
[2024-06-16T16:50:20.287+0530] {standard_task_runner.py:60} INFO - Started process 542 to run task
[2024-06-16T16:50:20.293+0530] {standard_task_runner.py:87} INFO - Running: ['airflow', 'tasks', 'run', 'weather_dag_etl', 'check_whether_api_ready', 'manual__2024-06-16T11:02:22.554439+00:00', '--job-id', '8', '--raw', '--subdir', 'DAGS_FOLDER/weather_dag_etl.py', '--cfg-path', '/tmp/tmp9i0iulpy']
[2024-06-16T16:50:20.298+0530] {standard_task_runner.py:88} INFO - Job 8: Subtask check_whether_api_ready
[2024-06-16T16:50:20.653+0530] {logging_mixin.py:188} INFO - Changing /mnt/d/Programs/weather etl/logs/dag_id=weather_dag_etl/run_id=manual__2024-06-16T11:02:22.554439+00:00/task_id=check_whether_api_ready permission to 509
[2024-06-16T16:50:20.658+0530] {task_command.py:423} INFO - Running <TaskInstance: weather_dag_etl.check_whether_api_ready manual__2024-06-16T11:02:22.554439+00:00 [running]> on host DESKTOP-ATOQU9B.localdomain
[2024-06-16T16:50:21.339+0530] {taskinstance.py:2480} INFO - Exporting env vars: AIRFLOW_CTX_DAG_EMAIL='email@udit.com' AIRFLOW_CTX_DAG_OWNER='udit' AIRFLOW_CTX_DAG_ID='weather_dag_etl' AIRFLOW_CTX_TASK_ID='check_whether_api_ready' AIRFLOW_CTX_EXECUTION_DATE='2024-06-16T11:02:22.554439+00:00' AIRFLOW_CTX_TRY_NUMBER='2' AIRFLOW_CTX_DAG_RUN_ID='manual__2024-06-16T11:02:22.554439+00:00'
[2024-06-16T16:50:21.342+0530] {http.py:130} INFO - Poking: https://api.openweathermap.org/data/2.5/weather?q=Portland&APPID=***
[2024-06-16T16:50:21.401+0530] {base.py:83} INFO - Using connection ID 'weathermap_api' for task execution.
[2024-06-16T16:50:21.819+0530] {http.py:178} ERROR - HTTP error: Not Found
[2024-06-16T16:50:21.822+0530] {http.py:179} ERROR - <html>
<head><title>404 Not Found</title></head>
<body>
<center><h1>404 Not Found</h1></center>
<hr><center>openresty</center>
</body>
</html>

[2024-06-16T16:51:21.871+0530] {http.py:130} INFO - Poking: https://api.openweathermap.org/data/2.5/weather?q=Portland&APPID=***
[2024-06-16T16:51:22.000+0530] {base.py:83} INFO - Using connection ID 'weathermap_api' for task execution.
[2024-06-16T16:51:22.764+0530] {http.py:178} ERROR - HTTP error: Not Found
[2024-06-16T16:51:22.767+0530] {http.py:179} ERROR - <html>
<head><title>404 Not Found</title></head>
<body>
<center><h1>404 Not Found</h1></center>
<hr><center>openresty</center>
</body>
</html>

[2024-06-16T16:52:22.796+0530] {http.py:130} INFO - Poking: https://api.openweathermap.org/data/2.5/weather?q=Portland&APPID=***
[2024-06-16T16:52:23.144+0530] {base.py:83} INFO - Using connection ID 'weathermap_api' for task execution.
[2024-06-16T16:52:23.356+0530] {http.py:178} ERROR - HTTP error: Not Found
[2024-06-16T16:52:23.361+0530] {http.py:179} ERROR - <html>
<head><title>404 Not Found</title></head>
<body>
<center><h1>404 Not Found</h1></center>
<hr><center>openresty</center>
</body>
</html>

[2024-06-16T16:53:23.425+0530] {http.py:130} INFO - Poking: https://api.openweathermap.org/data/2.5/weather?q=Portland&APPID=***
[2024-06-16T16:53:23.439+0530] {base.py:83} INFO - Using connection ID 'weathermap_api' for task execution.
[2024-06-16T16:53:23.646+0530] {http.py:178} ERROR - HTTP error: Not Found
[2024-06-16T16:53:23.648+0530] {http.py:179} ERROR - <html>
<head><title>404 Not Found</title></head>
<body>
<center><h1>404 Not Found</h1></center>
<hr><center>openresty</center>
</body>
</html>

[2024-06-16T16:54:23.677+0530] {http.py:130} INFO - Poking: https://api.openweathermap.org/data/2.5/weather?q=Portland&APPID=***
[2024-06-16T16:54:23.693+0530] {base.py:83} INFO - Using connection ID 'weathermap_api' for task execution.
[2024-06-16T16:54:23.979+0530] {http.py:178} ERROR - HTTP error: Not Found
[2024-06-16T16:54:23.981+0530] {http.py:179} ERROR - <html>
<head><title>404 Not Found</title></head>
<body>
<center><h1>404 Not Found</h1></center>
<hr><center>openresty</center>
</body>
</html>

[2024-06-16T16:55:24.045+0530] {http.py:130} INFO - Poking: https://api.openweathermap.org/data/2.5/weather?q=Portland&APPID=***
[2024-06-16T16:55:24.069+0530] {base.py:83} INFO - Using connection ID 'weathermap_api' for task execution.
[2024-06-16T16:55:24.310+0530] {http.py:178} ERROR - HTTP error: Not Found
[2024-06-16T16:55:24.312+0530] {http.py:179} ERROR - <html>
<head><title>404 Not Found</title></head>
<body>
<center><h1>404 Not Found</h1></center>
<hr><center>openresty</center>
</body>
</html>

[2024-06-16T16:56:15.751+0530] {process_utils.py:131} INFO - Sending 15 to group 542. PIDs of all processes in the group: [542]
[2024-06-16T16:56:15.764+0530] {process_utils.py:86} INFO - Sending the signal 15 to group 542
[2024-06-16T16:56:15.767+0530] {taskinstance.py:2450} ERROR - Received SIGTERM. Terminating subprocesses.
[2024-06-16T16:56:15.802+0530] {taskinstance.py:2698} ERROR - Task failed with exception
Traceback (most recent call last):
  File "/mnt/d/Programs/weather etl/airflow-venv/lib/python3.8/site-packages/airflow/models/taskinstance.py", line 433, in _execute_task
    result = execute_callable(context=context, **execute_callable_kwargs)
  File "/mnt/d/Programs/weather etl/airflow-venv/lib/python3.8/site-packages/airflow/sensors/base.py", line 293, in execute
    time.sleep(self._get_next_poke_interval(started_at, run_duration, try_number))
  File "/mnt/d/Programs/weather etl/airflow-venv/lib/python3.8/site-packages/airflow/models/taskinstance.py", line 2452, in signal_handler
    raise AirflowException("Task received SIGTERM signal")
airflow.exceptions.AirflowException: Task received SIGTERM signal
[2024-06-16T16:56:16.335+0530] {taskinstance.py:1138} INFO - Marking task as UP_FOR_RETRY. dag_id=weather_dag_etl, task_id=check_whether_api_ready, execution_date=20240616T110222, start_date=20240616T112020, end_date=20240616T112616
[2024-06-16T16:56:16.603+0530] {standard_task_runner.py:107} ERROR - Failed to execute job 8 for task check_whether_api_ready (Task received SIGTERM signal; 542)
[2024-06-16T16:56:16.654+0530] {process_utils.py:79} INFO - Process psutil.Process(pid=542, status='terminated', exitcode=1, started='16:50:19') (542) terminated with exit code 1
