[2024-06-16T16:33:38.498+0530] {logging_mixin.py:188} INFO - Changing /mnt/d/Programs/weather etl/logs/dag_id=weather_dag_etl/run_id=manual__2024-06-16T11:02:22.554439+00:00/task_id=check_whether_api_ready permission to 509
[2024-06-16T16:33:38.910+0530] {logging_mixin.py:188} INFO - Changing /mnt/d/Programs/weather etl/logs/dag_id=weather_dag_etl/run_id=manual__2024-06-16T11:02:22.554439+00:00/task_id=check_whether_api_ready permission to 509
[2024-06-16T16:33:38.948+0530] {taskinstance.py:1956} INFO - Dependencies all met for dep_context=non-requeueable deps ti=<TaskInstance: weather_dag_etl.check_whether_api_ready manual__2024-06-16T11:02:22.554439+00:00 [queued]>
[2024-06-16T16:33:38.971+0530] {taskinstance.py:1956} INFO - Dependencies all met for dep_context=requeueable deps ti=<TaskInstance: weather_dag_etl.check_whether_api_ready manual__2024-06-16T11:02:22.554439+00:00 [queued]>
[2024-06-16T16:33:38.973+0530] {taskinstance.py:2170} INFO - Starting attempt 1 of 3
[2024-06-16T16:33:39.115+0530] {taskinstance.py:2191} INFO - Executing <Task(HttpSensor): check_whether_api_ready> on 2024-06-16 11:02:22.554439+00:00
[2024-06-16T16:33:39.128+0530] {standard_task_runner.py:60} INFO - Started process 405 to run task
[2024-06-16T16:33:39.134+0530] {standard_task_runner.py:87} INFO - Running: ['airflow', 'tasks', 'run', 'weather_dag_etl', 'check_whether_api_ready', 'manual__2024-06-16T11:02:22.554439+00:00', '--job-id', '3', '--raw', '--subdir', 'DAGS_FOLDER/weather_dag_etl.py', '--cfg-path', '/tmp/tmpgn85c98b']
[2024-06-16T16:33:39.139+0530] {standard_task_runner.py:88} INFO - Job 3: Subtask check_whether_api_ready
[2024-06-16T16:33:39.355+0530] {logging_mixin.py:188} INFO - Changing /mnt/d/Programs/weather etl/logs/dag_id=weather_dag_etl/run_id=manual__2024-06-16T11:02:22.554439+00:00/task_id=check_whether_api_ready permission to 509
[2024-06-16T16:33:39.359+0530] {task_command.py:423} INFO - Running <TaskInstance: weather_dag_etl.check_whether_api_ready manual__2024-06-16T11:02:22.554439+00:00 [running]> on host DESKTOP-ATOQU9B.localdomain
[2024-06-16T16:33:39.764+0530] {taskinstance.py:2480} INFO - Exporting env vars: AIRFLOW_CTX_DAG_EMAIL='email@udit.com' AIRFLOW_CTX_DAG_OWNER='udit' AIRFLOW_CTX_DAG_ID='weather_dag_etl' AIRFLOW_CTX_TASK_ID='check_whether_api_ready' AIRFLOW_CTX_EXECUTION_DATE='2024-06-16T11:02:22.554439+00:00' AIRFLOW_CTX_TRY_NUMBER='1' AIRFLOW_CTX_DAG_RUN_ID='manual__2024-06-16T11:02:22.554439+00:00'
[2024-06-16T16:33:39.766+0530] {http.py:130} INFO - Poking: https://api.openweathermap.org/data/2.5/weather?q=Portland&APPID=dc1520bbfe7cca5c5265926aa4bef28f
[2024-06-16T16:33:39.816+0530] {base.py:83} INFO - Using connection ID 'weathermap_api' for task execution.
[2024-06-16T16:33:40.128+0530] {http.py:178} ERROR - HTTP error: Not Found
[2024-06-16T16:33:40.130+0530] {http.py:179} ERROR - <html>
<head><title>404 Not Found</title></head>
<body>
<center><h1>404 Not Found</h1></center>
<hr><center>openresty</center>
</body>
</html>

[2024-06-16T16:34:40.157+0530] {http.py:130} INFO - Poking: https://api.openweathermap.org/data/2.5/weather?q=Portland&APPID=dc1520bbfe7cca5c5265926aa4bef28f
[2024-06-16T16:34:40.175+0530] {base.py:83} INFO - Using connection ID 'weathermap_api' for task execution.
[2024-06-16T16:34:40.412+0530] {http.py:178} ERROR - HTTP error: Not Found
[2024-06-16T16:34:40.414+0530] {http.py:179} ERROR - <html>
<head><title>404 Not Found</title></head>
<body>
<center><h1>404 Not Found</h1></center>
<hr><center>openresty</center>
</body>
</html>

[2024-06-16T16:34:41.349+0530] {local_task_job_runner.py:302} WARNING - State of this instance has been externally set to restarting. Terminating instance.
[2024-06-16T16:34:41.356+0530] {process_utils.py:131} INFO - Sending Signals.SIGTERM to group 405. PIDs of all processes in the group: [405]
[2024-06-16T16:34:41.360+0530] {process_utils.py:86} INFO - Sending the signal Signals.SIGTERM to group 405
[2024-06-16T16:34:41.363+0530] {taskinstance.py:2450} ERROR - Received SIGTERM. Terminating subprocesses.
[2024-06-16T16:34:41.384+0530] {taskinstance.py:2698} ERROR - Task failed with exception
Traceback (most recent call last):
  File "/mnt/d/Programs/weather etl/airflow-venv/lib/python3.8/site-packages/airflow/models/taskinstance.py", line 433, in _execute_task
    result = execute_callable(context=context, **execute_callable_kwargs)
  File "/mnt/d/Programs/weather etl/airflow-venv/lib/python3.8/site-packages/airflow/sensors/base.py", line 293, in execute
    time.sleep(self._get_next_poke_interval(started_at, run_duration, try_number))
  File "/mnt/d/Programs/weather etl/airflow-venv/lib/python3.8/site-packages/airflow/models/taskinstance.py", line 2452, in signal_handler
    raise AirflowException("Task received SIGTERM signal")
airflow.exceptions.AirflowException: Task received SIGTERM signal
[2024-06-16T16:34:41.400+0530] {taskinstance.py:1138} INFO - Marking task as UP_FOR_RETRY. dag_id=weather_dag_etl, task_id=check_whether_api_ready, execution_date=20240616T110222, start_date=20240616T110338, end_date=20240616T110441
[2024-06-16T16:34:41.574+0530] {standard_task_runner.py:107} ERROR - Failed to execute job 3 for task check_whether_api_ready (Task received SIGTERM signal; 405)
[2024-06-16T16:34:41.617+0530] {process_utils.py:79} INFO - Process psutil.Process(pid=405, status='terminated', exitcode=1, started='16:33:38') (405) terminated with exit code 1
