[2024-06-16T16:57:12.943+0530] {logging_mixin.py:188} INFO - Changing /mnt/d/Programs/weather etl/logs/dag_id=weather_dag_etl/run_id=manual__2024-06-16T11:02:22.554439+00:00/task_id=check_whether_api_ready permission to 509
[2024-06-16T16:57:13.255+0530] {logging_mixin.py:188} INFO - Changing /mnt/d/Programs/weather etl/logs/dag_id=weather_dag_etl/run_id=manual__2024-06-16T11:02:22.554439+00:00/task_id=check_whether_api_ready permission to 509
[2024-06-16T16:57:13.290+0530] {taskinstance.py:1946} INFO - Dependencies not met for <TaskInstance: weather_dag_etl.check_whether_api_ready manual__2024-06-16T11:02:22.554439+00:00 [up_for_retry]>, dependency 'Not In Retry Period' FAILED: Task is not ready for retry yet but will be retried automatically. Current date is 2024-06-16T11:27:13.290516+00:00 and task will be retried at 2024-06-16T11:28:16.333431+00:00.
[2024-06-16T16:57:13.305+0530] {local_task_job_runner.py:160} INFO - Task is not able to be run
[2024-06-16T17:03:43.644+0530] {logging_mixin.py:188} INFO - Changing /mnt/d/Programs/weather etl/logs/dag_id=weather_dag_etl/run_id=manual__2024-06-16T11:02:22.554439+00:00/task_id=check_whether_api_ready permission to 509
[2024-06-16T17:03:43.942+0530] {logging_mixin.py:188} INFO - Changing /mnt/d/Programs/weather etl/logs/dag_id=weather_dag_etl/run_id=manual__2024-06-16T11:02:22.554439+00:00/task_id=check_whether_api_ready permission to 509
[2024-06-16T17:03:43.969+0530] {taskinstance.py:1956} INFO - Dependencies all met for dep_context=non-requeueable deps ti=<TaskInstance: weather_dag_etl.check_whether_api_ready manual__2024-06-16T11:02:22.554439+00:00 [queued]>
[2024-06-16T17:03:43.983+0530] {taskinstance.py:1956} INFO - Dependencies all met for dep_context=requeueable deps ti=<TaskInstance: weather_dag_etl.check_whether_api_ready manual__2024-06-16T11:02:22.554439+00:00 [queued]>
[2024-06-16T17:03:43.984+0530] {taskinstance.py:2170} INFO - Starting attempt 3 of 3
[2024-06-16T17:03:44.121+0530] {taskinstance.py:2191} INFO - Executing <Task(HttpSensor): check_whether_api_ready> on 2024-06-16 11:02:22.554439+00:00
[2024-06-16T17:03:44.126+0530] {standard_task_runner.py:60} INFO - Started process 659 to run task
[2024-06-16T17:03:44.131+0530] {standard_task_runner.py:87} INFO - Running: ['airflow', 'tasks', 'run', 'weather_dag_etl', 'check_whether_api_ready', 'manual__2024-06-16T11:02:22.554439+00:00', '--job-id', '13', '--raw', '--subdir', 'DAGS_FOLDER/weather_dag_etl.py', '--cfg-path', '/tmp/tmpmebzm_5a']
[2024-06-16T17:03:44.136+0530] {standard_task_runner.py:88} INFO - Job 13: Subtask check_whether_api_ready
[2024-06-16T17:03:44.414+0530] {logging_mixin.py:188} INFO - Changing /mnt/d/Programs/weather etl/logs/dag_id=weather_dag_etl/run_id=manual__2024-06-16T11:02:22.554439+00:00/task_id=check_whether_api_ready permission to 509
[2024-06-16T17:03:44.419+0530] {task_command.py:423} INFO - Running <TaskInstance: weather_dag_etl.check_whether_api_ready manual__2024-06-16T11:02:22.554439+00:00 [running]> on host DESKTOP-ATOQU9B.localdomain
[2024-06-16T17:03:44.638+0530] {taskinstance.py:2480} INFO - Exporting env vars: AIRFLOW_CTX_DAG_EMAIL='email@udit.com' AIRFLOW_CTX_DAG_OWNER='udit' AIRFLOW_CTX_DAG_ID='weather_dag_etl' AIRFLOW_CTX_TASK_ID='check_whether_api_ready' AIRFLOW_CTX_EXECUTION_DATE='2024-06-16T11:02:22.554439+00:00' AIRFLOW_CTX_TRY_NUMBER='3' AIRFLOW_CTX_DAG_RUN_ID='manual__2024-06-16T11:02:22.554439+00:00'
[2024-06-16T17:03:44.640+0530] {http.py:130} INFO - Poking: https://api.openweathermap.org/data/2.5/weather?q=Portland&APPID=***
[2024-06-16T17:03:44.657+0530] {base.py:83} INFO - Using connection ID 'weathermap_api' for task execution.
[2024-06-16T17:03:44.937+0530] {http.py:178} ERROR - HTTP error: Not Found
[2024-06-16T17:03:44.941+0530] {http.py:179} ERROR - <html>
<head><title>404 Not Found</title></head>
<body>
<center><h1>404 Not Found</h1></center>
<hr><center>openresty</center>
</body>
</html>

[2024-06-16T17:04:44.962+0530] {http.py:130} INFO - Poking: https://api.openweathermap.org/data/2.5/weather?q=Portland&APPID=***
[2024-06-16T17:04:45.035+0530] {base.py:83} INFO - Using connection ID 'weathermap_api' for task execution.
[2024-06-16T17:04:45.262+0530] {http.py:178} ERROR - HTTP error: Not Found
[2024-06-16T17:04:45.264+0530] {http.py:179} ERROR - <html>
<head><title>404 Not Found</title></head>
<body>
<center><h1>404 Not Found</h1></center>
<hr><center>openresty</center>
</body>
</html>

[2024-06-16T17:05:40.927+0530] {local_task_job_runner.py:302} WARNING - State of this instance has been externally set to failed. Terminating instance.
[2024-06-16T17:05:40.929+0530] {process_utils.py:131} INFO - Sending 15 to group 659. PIDs of all processes in the group: [659]
[2024-06-16T17:05:40.930+0530] {process_utils.py:86} INFO - Sending the signal 15 to group 659
[2024-06-16T17:05:40.932+0530] {taskinstance.py:2450} ERROR - Received SIGTERM. Terminating subprocesses.
[2024-06-16T17:05:41.064+0530] {process_utils.py:79} INFO - Process psutil.Process(pid=659, status='terminated', exitcode=0, started='17:03:43') (659) terminated with exit code 0
