[2024-06-17T09:44:38.908+0530] {logging_mixin.py:188} INFO - Changing /mnt/d/Programs/weather etl/logs/dag_id=weather_dag_etl/run_id=scheduled__2024-06-16T00:00:00+00:00/task_id=check_whether_api_ready permission to 509
[2024-06-17T09:44:39.422+0530] {logging_mixin.py:188} INFO - Changing /mnt/d/Programs/weather etl/logs/dag_id=weather_dag_etl/run_id=scheduled__2024-06-16T00:00:00+00:00/task_id=check_whether_api_ready permission to 509
[2024-06-17T09:44:39.504+0530] {taskinstance.py:1956} INFO - Dependencies all met for dep_context=non-requeueable deps ti=<TaskInstance: weather_dag_etl.check_whether_api_ready scheduled__2024-06-16T00:00:00+00:00 [queued]>
[2024-06-17T09:44:39.607+0530] {taskinstance.py:1956} INFO - Dependencies all met for dep_context=requeueable deps ti=<TaskInstance: weather_dag_etl.check_whether_api_ready scheduled__2024-06-16T00:00:00+00:00 [queued]>
[2024-06-17T09:44:39.609+0530] {taskinstance.py:2170} INFO - Starting attempt 1 of 4
[2024-06-17T09:44:39.840+0530] {taskinstance.py:2191} INFO - Executing <Task(HttpSensor): check_whether_api_ready> on 2024-06-16 00:00:00+00:00
[2024-06-17T09:44:39.846+0530] {standard_task_runner.py:60} INFO - Started process 78 to run task
[2024-06-17T09:44:39.853+0530] {standard_task_runner.py:87} INFO - Running: ['airflow', 'tasks', 'run', 'weather_dag_etl', 'check_whether_api_ready', 'scheduled__2024-06-16T00:00:00+00:00', '--job-id', '116', '--raw', '--subdir', 'DAGS_FOLDER/weather_dag_etl.py', '--cfg-path', '/tmp/tmp3yk0zg7h']
[2024-06-17T09:44:39.858+0530] {standard_task_runner.py:88} INFO - Job 116: Subtask check_whether_api_ready
[2024-06-17T09:44:40.393+0530] {logging_mixin.py:188} INFO - Changing /mnt/d/Programs/weather etl/logs/dag_id=weather_dag_etl/run_id=scheduled__2024-06-16T00:00:00+00:00/task_id=check_whether_api_ready permission to 509
[2024-06-17T09:44:40.401+0530] {task_command.py:423} INFO - Running <TaskInstance: weather_dag_etl.check_whether_api_ready scheduled__2024-06-16T00:00:00+00:00 [running]> on host DESKTOP-ATOQU9B.localdomain
[2024-06-17T09:44:41.274+0530] {taskinstance.py:2480} INFO - Exporting env vars: AIRFLOW_CTX_DAG_EMAIL='email@udit.com' AIRFLOW_CTX_DAG_OWNER='udit' AIRFLOW_CTX_DAG_ID='weather_dag_etl' AIRFLOW_CTX_TASK_ID='check_whether_api_ready' AIRFLOW_CTX_EXECUTION_DATE='2024-06-16T00:00:00+00:00' AIRFLOW_CTX_TRY_NUMBER='1' AIRFLOW_CTX_DAG_RUN_ID='scheduled__2024-06-16T00:00:00+00:00'
[2024-06-17T09:44:41.278+0530] {http.py:130} INFO - Poking: /data/2.5/weather?q=Chennai&APPID=2cd05943463cf3fea1ab294c51190fb2
[2024-06-17T09:44:41.330+0530] {base.py:83} INFO - Using connection ID 'weathermap_api' for task execution.
[2024-06-17T09:44:41.971+0530] {http.py:178} ERROR - HTTP error: Unauthorized
[2024-06-17T09:44:41.974+0530] {http.py:179} ERROR - {"cod":401, "message": "Invalid API key. Please see https://openweathermap.org/faq#error401 for more info."}
[2024-06-17T09:44:41.991+0530] {taskinstance.py:2698} ERROR - Task failed with exception
Traceback (most recent call last):
  File "/mnt/d/Programs/weather etl/airflow-venv/lib/python3.8/site-packages/airflow/providers/http/hooks/http.py", line 176, in check_response
    response.raise_for_status()
  File "/mnt/d/Programs/weather etl/airflow-venv/lib/python3.8/site-packages/requests/models.py", line 1021, in raise_for_status
    raise HTTPError(http_error_msg, response=self)
requests.exceptions.HTTPError: 401 Client Error: Unauthorized for url: https://api.openweathermap.org/data/2.5/weather?q=Chennai&APPID=2cd05943463cf3fea1ab294c51190fb2

During handling of the above exception, another exception occurred:

Traceback (most recent call last):
  File "/mnt/d/Programs/weather etl/airflow-venv/lib/python3.8/site-packages/airflow/models/taskinstance.py", line 433, in _execute_task
    result = execute_callable(context=context, **execute_callable_kwargs)
  File "/mnt/d/Programs/weather etl/airflow-venv/lib/python3.8/site-packages/airflow/sensors/base.py", line 265, in execute
    raise e
  File "/mnt/d/Programs/weather etl/airflow-venv/lib/python3.8/site-packages/airflow/sensors/base.py", line 247, in execute
    poke_return = self.poke(context)
  File "/mnt/d/Programs/weather etl/airflow-venv/lib/python3.8/site-packages/airflow/providers/http/sensors/http.py", line 148, in poke
    raise exc
  File "/mnt/d/Programs/weather etl/airflow-venv/lib/python3.8/site-packages/airflow/providers/http/sensors/http.py", line 132, in poke
    response = hook.run(
  File "/mnt/d/Programs/weather etl/airflow-venv/lib/python3.8/site-packages/airflow/providers/http/hooks/http.py", line 166, in run
    return self.run_and_check(session, prepped_request, extra_options)
  File "/mnt/d/Programs/weather etl/airflow-venv/lib/python3.8/site-packages/airflow/providers/http/hooks/http.py", line 217, in run_and_check
    self.check_response(response)
  File "/mnt/d/Programs/weather etl/airflow-venv/lib/python3.8/site-packages/airflow/providers/http/hooks/http.py", line 180, in check_response
    raise AirflowException(str(response.status_code) + ":" + response.reason)
airflow.exceptions.AirflowException: 401:Unauthorized
[2024-06-17T09:44:42.144+0530] {taskinstance.py:1138} INFO - Marking task as UP_FOR_RETRY. dag_id=weather_dag_etl, task_id=check_whether_api_ready, execution_date=20240616T000000, start_date=20240617T041439, end_date=20240617T041442
[2024-06-17T09:44:42.619+0530] {standard_task_runner.py:107} ERROR - Failed to execute job 116 for task check_whether_api_ready (401:Unauthorized; 78)
[2024-06-17T09:44:42.642+0530] {local_task_job_runner.py:234} INFO - Task exited with return code 1
[2024-06-17T09:44:42.716+0530] {taskinstance.py:3280} INFO - 0 downstream tasks scheduled from follow-on schedule check
