[2024-06-16T19:25:47.488+0530] {logging_mixin.py:188} INFO - Changing /mnt/d/Programs/weather etl/logs/dag_id=weather_dag_etl/run_id=manual__2024-06-16T13:48:18.821159+00:00/task_id=load_to_s3_bucket permission to 509
[2024-06-16T19:25:47.792+0530] {logging_mixin.py:188} INFO - Changing /mnt/d/Programs/weather etl/logs/dag_id=weather_dag_etl/run_id=manual__2024-06-16T13:48:18.821159+00:00/task_id=load_to_s3_bucket permission to 509
[2024-06-16T19:25:47.813+0530] {taskinstance.py:1956} INFO - Dependencies all met for dep_context=non-requeueable deps ti=<TaskInstance: weather_dag_etl.load_to_s3_bucket manual__2024-06-16T13:48:18.821159+00:00 [queued]>
[2024-06-16T19:25:47.826+0530] {taskinstance.py:1956} INFO - Dependencies all met for dep_context=requeueable deps ti=<TaskInstance: weather_dag_etl.load_to_s3_bucket manual__2024-06-16T13:48:18.821159+00:00 [queued]>
[2024-06-16T19:25:47.828+0530] {taskinstance.py:2170} INFO - Starting attempt 1 of 3
[2024-06-16T19:25:49.299+0530] {taskinstance.py:2191} INFO - Executing <Task(PythonOperator): load_to_s3_bucket> on 2024-06-16 13:48:18.821159+00:00
[2024-06-16T19:25:49.307+0530] {standard_task_runner.py:60} INFO - Started process 5438 to run task
[2024-06-16T19:25:49.311+0530] {standard_task_runner.py:87} INFO - Running: ['airflow', 'tasks', 'run', 'weather_dag_etl', 'load_to_s3_bucket', 'manual__2024-06-16T13:48:18.821159+00:00', '--job-id', '85', '--raw', '--subdir', 'DAGS_FOLDER/weather_dag_etl.py', '--cfg-path', '/tmp/tmp6sa9_lah']
[2024-06-16T19:25:49.316+0530] {standard_task_runner.py:88} INFO - Job 85: Subtask load_to_s3_bucket
[2024-06-16T19:25:49.494+0530] {logging_mixin.py:188} INFO - Changing /mnt/d/Programs/weather etl/logs/dag_id=weather_dag_etl/run_id=manual__2024-06-16T13:48:18.821159+00:00/task_id=load_to_s3_bucket permission to 509
[2024-06-16T19:25:49.497+0530] {task_command.py:423} INFO - Running <TaskInstance: weather_dag_etl.load_to_s3_bucket manual__2024-06-16T13:48:18.821159+00:00 [running]> on host DESKTOP-ATOQU9B.localdomain
[2024-06-16T19:25:49.961+0530] {taskinstance.py:2480} INFO - Exporting env vars: AIRFLOW_CTX_DAG_EMAIL='email@udit.com' AIRFLOW_CTX_DAG_OWNER='udit' AIRFLOW_CTX_DAG_ID='weather_dag_etl' AIRFLOW_CTX_TASK_ID='load_to_s3_bucket' AIRFLOW_CTX_EXECUTION_DATE='2024-06-16T13:48:18.821159+00:00' AIRFLOW_CTX_TRY_NUMBER='1' AIRFLOW_CTX_DAG_RUN_ID='manual__2024-06-16T13:48:18.821159+00:00'
[2024-06-16T19:25:49.963+0530] {taskinstance.py:2698} ERROR - Task failed with exception
Traceback (most recent call last):
  File "/mnt/d/Programs/weather etl/airflow-venv/lib/python3.8/site-packages/airflow/models/taskinstance.py", line 433, in _execute_task
    result = execute_callable(context=context, **execute_callable_kwargs)
  File "/mnt/d/Programs/weather etl/airflow-venv/lib/python3.8/site-packages/airflow/operators/python.py", line 199, in execute
    return_value = self.execute_callable()
  File "/mnt/d/Programs/weather etl/airflow-venv/lib/python3.8/site-packages/airflow/operators/python.py", line 216, in execute_callable
    return self.python_callable(*self.op_args, **self.op_kwargs)
  File "/mnt/d/Programs/weather etl/dags/weather_dag_etl.py", line 54, in load_data_to_s3_bucket
    for filename in os.listdir("/weather_data"):
FileNotFoundError: [Errno 2] No such file or directory: '/weather_data'
[2024-06-16T19:25:50.017+0530] {taskinstance.py:1138} INFO - Marking task as UP_FOR_RETRY. dag_id=weather_dag_etl, task_id=load_to_s3_bucket, execution_date=20240616T134818, start_date=20240616T135547, end_date=20240616T135550
[2024-06-16T19:25:50.186+0530] {standard_task_runner.py:107} ERROR - Failed to execute job 85 for task load_to_s3_bucket ([Errno 2] No such file or directory: '/weather_data'; 5438)
[2024-06-16T19:25:50.211+0530] {local_task_job_runner.py:234} INFO - Task exited with return code 1
[2024-06-16T19:25:50.240+0530] {taskinstance.py:3280} INFO - 0 downstream tasks scheduled from follow-on schedule check
